xception in Tkinter callback
Traceback (most recent call last):
  File "/usr/lib/python3.11/tkinter/__init__.py", line 1948, in __call__
    return self.func(*args)
           ^^^^^^^^^^^^^^^^
  File "/home/pi/Downloads/ilyass-main/PythonProject/Window.py", line 135, in <lambda>
    start_btn = tk.Button(frame3, text="Activer", command=lambda: control_alarm_manual(True), background="lightgreen", pady=5, state=tk.DISABLED)
                                                                  ^^^^^^^^^^^^^^^^^^^^
NameError: name 'control_alarm_manual' is not defined
